<?xml version="1.0" encoding="utf-8"?>
<robot xmlns:xacro="http://www.ros.org/wiki/xacro" name="swarm_drone">

  <!-- Include the materials and colors -->
  <xacro:include filename="$(find drone_description)/urdf/materials_and_colors.xacro"/>

  <!-- Main quadcopter link -->  
  <link name="base_link">
    <collision name="base_collision">
      <origin rpy="0.00000 0.00000 0.00000" xyz="0.00000 -0.00000 0.00000"/>
      <geometry>
        <mesh filename="package://drone_description/meshes/collisions/base.stl" scale="0.00069 0.00069 0.00069"/>
      </geometry>
    </collision>
    <inertial>
      <inertia ixx="0.00557" ixy="-0.00000" ixz="0.00005" iyy="0.00469" iyz="0.00000" izz="0.00449"/>
      <origin rpy="0.00000 0.00000 0.00000" xyz="-0.00011 -0.00005 0.02056"/>
      <mass value="0.32500"/>
    </inertial>
    <visual name="base">
      <origin rpy="0.00000 0.00000 0.00000" xyz="0.00000 -0.00000 0.00000"/>
      <material name="LandingRubber"/>
      <geometry>
        <mesh filename="package://drone_description/meshes/visuals/base.dae" scale="0.00069 0.00069 0.00069"/>
      </geometry>
    </visual>
  </link>

  <!-- Front left proppeller link -->
  <link name="proppeller_FL_link">
    <collision name="proppeller_FL_collision">
      <origin rpy="1.57080 -0.00000 0.00000" xyz="-0.00000 -0.00000 -0.00000"/>
      <geometry>
        <mesh filename="package://drone_description/meshes/collisions/prop_fl.stl" scale="0.01000 0.01000 0.01000"/>
      </geometry>
    </collision>
    <inertial>
      <inertia ixx="0.00007" ixy="0.00000" ixz="0.00000" iyy="0.00001" iyz="-0.00000" izz="0.00007"/>
      <origin rpy="0.00000 0.00000 0.00000" xyz="-0.00000 -0.00000 -0.00000"/>
      <mass value="0.05000"/>
    </inertial>
    <visual name="proppeller_FL">
      <origin rpy="1.57080 -0.00000 0.00000" xyz="-0.00000 -0.00000 -0.00000"/>
      <material name="green_metal"/>
      <geometry>
        <mesh filename="package://drone_description/meshes/visuals/prop_fl.dae" scale="0.01000 0.01000 0.01000"/>
      </geometry>
    </visual>
  </link>

  <!-- Front right proppeller link -->
  <link name="proppeller_FR_link">
    <collision name="proppeller_FR_collision">
      <origin rpy="1.57080 -0.00000 0.00000" xyz="0.00000 0.00000 -0.00000"/>
      <geometry>
        <mesh filename="package://drone_description/meshes/collisions/prop_fr.stl" scale="0.01000 0.01000 0.01000"/>
      </geometry>
    </collision>
    <inertial>
      <inertia ixx="0.00007" ixy="-0.00000" ixz="0.00000" iyy="0.00001" iyz="0.00000" izz="0.00007"/>
      <origin rpy="0.00000 0.00000 0.00000" xyz="0.00000 0.00000 -0.00000"/>
      <mass value="0.05000"/>
    </inertial>
    <visual name="proppeller_FR">
      <origin rpy="1.57080 -0.00000 0.00000" xyz="-0.00000 0.00000 -0.00000"/>
      <material name="green_metal"/>
      <geometry>
        <mesh filename="package://drone_description/meshes/visuals/prop_fr.dae" scale="0.01000 0.01000 0.01000"/>
      </geometry>
    </visual>
  </link>

  <!-- Back left proppeller link -->
  <link name="proppeller_BL_link">
    <collision name="proppeller_BL_collision">
      <origin rpy="1.57080 0.00000 0.00000" xyz="0.00000 -0.00000 -0.00000"/>
      <geometry>
        <mesh filename="package://drone_description/meshes/collisions/prop_bl.stl" scale="0.01000 0.01000 0.01000"/>
      </geometry>
    </collision>
    <inertial>
      <inertia ixx="0.00007" ixy="-0.00000" ixz="-0.00000" iyy="0.00001" iyz="-0.00000" izz="0.00007"/>
      <origin rpy="0.00000 0.00000 0.00000" xyz="0.00000 -0.00000 -0.00000"/>
      <mass value="0.05000"/>
    </inertial>
    <visual name="proppeller_BL">
      <origin rpy="1.57080 0.00000 0.00000" xyz="0.00000 -0.00000 -0.00000"/>
      <material name="green_metal"/>
      <geometry>
        <mesh filename="package://drone_description/meshes/visuals/prop_bl.dae" scale="0.01000 0.01000 0.01000"/>
      </geometry>
    </visual>
  </link>

  <!-- Back right proppeller link -->
  <link name="proppeller_BR_link">
    <collision name="proppeller_BR_collision">
      <origin rpy="1.57080 0.00000 0.00000" xyz="-0.00000 -0.00000 -0.00000"/>
      <geometry>
        <mesh filename="package://drone_description/meshes/collisions/prop_br.stl" scale="0.01000 0.01000 0.01000"/>
      </geometry>
    </collision>
    <inertial>
      <inertia ixx="0.00007" ixy="0.00000" ixz="-0.00000" iyy="0.00001" iyz="-0.00000" izz="0.00007"/>
      <origin rpy="0.00000 0.00000 0.00000" xyz="-0.00000 -0.00000 -0.00000"/>
      <mass value="0.05000"/>
    </inertial>
    <visual name="proppeller_BR">
      <origin rpy="1.57080 0.00000 0.00000" xyz="-0.00000 -0.00000 -0.00000"/>
      <material name="green_metal"/>
      <geometry>
        <mesh filename="package://drone_description/meshes/visuals/prop_br.dae" scale="0.01000 0.01000 0.01000"/>
      </geometry>
    </visual>
  </link>

  <!-- Camera 360 link -->
  <link name="camera_360_link">
    <sensor name="camera_360" type="camera">
      <origin rpy="1.55815 -1.48401 -1.52510" xyz="-0.02318 0.00259 -0.00057"/>
      <parent link="camera_360_link"/>
      <camera>
        <image>
          <width>640</width>
          <height>480</height>
          <hfov>1.57080</hfov>
        </image>
      </camera>
    </sensor>
    <collision name="camera_360_collision">
      <origin rpy="-1.67352 -0.01991 -0.11320" xyz="0.00062 0.00343 -0.00033"/>
      <geometry>
        <mesh filename="package://drone_description/meshes/collisions/camera_360.stl" scale="0.00069 0.00069 0.00069"/>
      </geometry>
    </collision>
    <inertial>
      <inertia ixx="0.00002" ixy="-0.00000" ixz="-0.00000" iyy="0.00003" iyz="-0.00000" izz="0.00003"/>
      <origin rpy="0.00000 0.00000 0.00000" xyz="-0.00276 -0.00079 0.00002"/>
      <mass value="0.12500"/>
    </inertial>
    <visual name="camera_360">
      <origin rpy="-1.67352 -0.01991 -0.11320" xyz="0.00062 0.00343 -0.00033"/>
      <material name="RailsRubber"/>
      <geometry>
        <mesh filename="package://drone_description/meshes/visuals/camera_360.dae" scale="0.00069 0.00069 0.00069"/>
      </geometry>
    </visual>
  </link>
  
  <!-- Camera joint 1 link -->
  <link name="camera_joint_1_link">
    <collision name="camera_joint_1_collision">
      <origin rpy="3.14159 0.00000 -3.14159" xyz="-0.03933 -0.00000 0.01897"/>
      <geometry>
        <mesh filename="package://drone_description/meshes/collisions/camera_joint1.stl" scale="0.00069 0.00069 0.00069"/>
      </geometry>
    </collision>
    <inertial>
      <inertia ixx="0.00100" ixy="0.00000" ixz="0.00000" iyy="0.00100" iyz="0.00000" izz="0.00100"/>
      <origin rpy="0.00000 0.00000 0.00000" xyz="0.00000 0.00000 -0.00000"/>
      <mass value="0.12500"/>
    </inertial>
    <visual name="camera_joint_1">
      <origin rpy="3.14159 0.00000 3.12071" xyz="-0.03932 0.00082 0.01897"/>
      <material name="RailsAntennaHolder"/>
      <geometry>
        <mesh filename="package://drone_description/meshes/visuals/camera_joint1.dae" scale="0.00069 0.00069 0.00069"/>
      </geometry>
    </visual>
  </link>

  <!-- Camera joint 2 link -->
  <link name="camera_joint_2_link">
    <collision name="camera_joint_2_collision">
      <origin rpy="1.57078 -1.54991 -1.57078" xyz="0.00022 0.00039 -0.01975"/>
      <geometry>
        <mesh filename="package://drone_description/meshes/collisions/camera_joint2.stl" scale="0.00069 0.00069 0.00069"/>
      </geometry>
    </collision>
    <inertial>
      <inertia ixx="0.00004" ixy="-0.00000" ixz="0.00000" iyy="0.00002" iyz="-0.00000" izz="0.00005"/>
      <origin rpy="0.00000 0.00000 0.00000" xyz="0.00027 -0.00019 -0.01827"/>
      <mass value="0.12500"/>
    </inertial>
    <visual name="camera_joint_2">
      <origin rpy="0.66324 -1.57080 -0.63013" xyz="0.00021 0.00045 -0.01976"/>
      <material name="Metal"/>
      <geometry>
        <mesh filename="package://drone_description/meshes/visuals/camera_joint2.dae" scale="0.00069 0.00069 0.00069"/>
      </geometry>
    </visual>
  </link>
  
  <!-- Depth camera link -->
  <link name="depth_camera_link">
    <sensor name="depth_camera" type="camera">
      <origin rpy="-1.57080 0.00000 0.00000" xyz="0.00000 0.00736 0.00000"/>
      <parent link="depth_camera_link"/>
      <camera>
        <image>
          <width>640</width>
          <height>480</height>
          <hfov>1.57080</hfov>
        </image>
      </camera>
    </sensor>
    <collision name="depth_camera_collision">
      <origin rpy="1.57080 0.00000 0.00000" xyz="0.00000 -0.00000 -0.00000"/>
      <geometry>
        <mesh filename="package://drone_description/meshes/collisions/depth_camera.stl" scale="0.01000 0.01000 0.01000"/>
      </geometry>
    </collision>
    <inertial>
      <inertia ixx="0.00003" ixy="-0.00000" ixz="0.00000" iyy="0.00000" iyz="-0.00000" izz="0.00003"/>
      <origin rpy="0.00000 0.00000 0.00000" xyz="0.00000 -0.00000 -0.00000"/>
      <mass value="0.05000"/>
    </inertial>
    <visual name="depth_camera">
      <origin rpy="1.57080 -0.00000 0.00000" xyz="0.00000 -0.00000 -0.00000"/>
      <material name="CameraMesh.003"/>
      <geometry>
        <mesh filename="package://drone_description/meshes/visuals/depth_camera.dae" scale="0.01000 0.01000 0.01000"/>
      </geometry>
    </visual>
  </link>

  <!-- Proppeller front left joint -->
  <joint name="proppeller_BL_link_joint" type="continuous">
    <limit lower="0.00000" upper="0.00000" effort="0.00000" velocity="0.00000"/>
    <origin rpy="0.00000 0.00000 -0.00000" xyz="0.18070 -0.17501 0.11613"/>
    <parent link="base_link"/>
    <child link="proppeller_BL_link"/>
    <axis xyz="0.00000 0.00000 1.00000"/>
  </joint>

  <!-- Proppeller front right joint -->
  <joint name="proppeller_BR_link_joint" type="continuous">
    <limit lower="0.00000" upper="0.00000" effort="0.00000" velocity="0.00000"/>
    <origin rpy="0.00000 0.00000 -0.00000" xyz="0.18070 0.17477 0.11613"/>
    <parent link="base_link"/>
    <child link="proppeller_BR_link"/>
    <axis xyz="0.00000 0.00000 -1.00000"/>
  </joint>

  <!-- Proppeller back left joint -->
  <joint name="proppeller_FL_link_joint" type="continuous">
    <limit lower="0.00000" upper="0.00000" effort="0.00000" velocity="0.00000"/>
    <origin rpy="0.00000 0.00000 -0.00000" xyz="-0.16902 -0.17494 0.11613"/>
    <parent link="base_link"/>
    <child link="proppeller_FL_link"/>
    <axis xyz="0.00000 0.00000 -1.00000"/>
  </joint>

  <!-- Proppeller back right joint -->
  <joint name="proppeller_FR_link_joint" type="continuous">
    <limit lower="0.00000" upper="0.00000" effort="0.00000" velocity="0.00000"/>
    <origin rpy="0.00000 0.00000 -0.00000" xyz="-0.16893 0.17474 0.11613"/>
    <parent link="base_link"/>
    <child link="proppeller_FR_link"/>
    <axis xyz="0.00000 0.00000 1.00000"/>
  </joint>


  <!-- Camera 360 joint -->
  <joint name="camera_360_link_joint" type="revolute">
    <limit lower="-3.14000" upper="3.14000" effort="0.00000" velocity="0.00000"/>
    <origin rpy="2.21817 -1.57080 -0.61426" xyz="0.00019 0.00002 -0.03339"/>
    <parent link="camera_joint_2_link"/>
    <child link="camera_360_link"/>
    <axis xyz="0.00000 0.00000 1.00000"/>
  </joint>

  <!-- Camera joint 1 joint -->
  <joint name="camera_joint_1_link_joint" type="revolute">
    <limit lower="-3.14000" upper="3.14000" effort="0.00000" velocity="0.00000"/>
    <origin rpy="3.14159 -0.00000 -3.14159" xyz="0.01099 -0.00017 -0.01909"/>
    <parent link="base_link"/>
    <child link="camera_joint_1_link"/>
    <axis xyz="0.00000 0.00000 1.00000"/>
  </joint>

  <!-- Camera joint 2 joint -->
  <joint name="camera_joint_2_link_joint" type="revolute">
    <limit lower="-3.14000" upper="3.14000" effort="0.00000" velocity="0.00000"/>
    <origin rpy="2.77664 -1.57080 -2.79753" xyz="-0.02223 0.00046 0.03019"/>
    <parent link="camera_joint_1_link"/>
    <child link="camera_joint_2_link"/>
    <axis xyz="0.00000 0.00000 1.00000"/>
  </joint>

  <!-- Depth camera joint -->
  <joint name="depth_camera_link_joint" type="fixed">
    <origin rpy="-0.00000 -0.00000 1.57080" xyz="-0.11887 -0.00145 0.07986"/>
    <parent link="base_link"/>
    <child link="depth_camera_link"/>
  </joint>

</robot>