<?xml version="1.0" ?>
<!-- =================================================================================== -->
<!-- |    This document was autogenerated by xacro from drone_model.xacro              | -->
<!-- |    EDITING THIS FILE BY HAND IS NOT RECOMMENDED                                 | -->
<!-- =================================================================================== -->
<robot name="drone_model">
  <!-- Define base_link properties -->
  <link name="base_link">
    <inertial>
      <origin rpy="0 0 0" xyz="-9.1847336179729E-05 0.000415033617555904 -0.000995363919215286"/>
      <mass value="0.254307892771006"/>
      <inertia ixx="0.00058785819039432" ixy="1.59211619501172e-07" ixz="7.61062796150718e-08" iyy="0.000540510823170516" iyz="-2.06165469438771e-08" izz="0.00109842132129949"/>
    </inertial>
    <visual name="base_link_visual">
      <origin rpy="0 0 0" xyz="0 0 0"/>
      <geometry>
        <mesh filename="/home/nidhood/Desktop/SWARN_PROJECT/src/drone_model/meshes/visuals/base_link.dae"/>
      </geometry>
    </visual>
    <collision name="base_link_collision">
      <origin rpy="0 0 0" xyz="0 0 0"/>
      <geometry>
        <mesh filename="/home/nidhood/Desktop/SWARN_PROJECT/src/drone_model/meshes/collisions/base_link.stl"/>
      </geometry>
    </collision>
  </link>
  <!-- Define prop_forwards_left_link properties -->
  <link name="prop_forwards_left_link">
    <inertial>
      <origin rpy="0 0 0" xyz="5.71642894409141E-07 -8.54929965155016E-08 0.0018576502110494"/>
      <mass value="0.00622580390535254"/>
      <inertia ixx="4.65686406510033e-06" ixy="1.40233492263942e-10" ixz="-2.825811940744e-12" iyy="4.65632288664103e-06" iyz="-2.90803707417964e-12" izz="9.1283491808267e-06"/>
    </inertial>
    <visual name="prop_forwards_left_link_visual">
      <origin rpy="0 0 0" xyz="0 0 0"/>
      <geometry>
        <mesh filename="/home/nidhood/Desktop/SWARN_PROJECT/src/drone_model/meshes/visuals/prop_forwards_left_link.dae"/>
      </geometry>
    </visual>
    <collision name="prop_forwards_left_link_collision">
      <origin rpy="0 0 0" xyz="0 0 0"/>
      <geometry>
        <mesh filename="/home/nidhood/Desktop/SWARN_PROJECT/src/drone_model/meshes/collisions/prop_forwards_left_link.stl"/>
      </geometry>
    </collision>
  </link>
  <!-- Define prop_forwards_left_link joint -->
  <joint name="joint_prop_forwards_left_link" type="continuous">
    <origin rpy="0 0 2.3562" xyz="-0.1 0.099994 0.026497"/>
    <parent link="base_link"/>
    <child link="prop_forwards_left_link"/>
    <axis xyz="0 0 1"/>
    <limit effort="100" lower="-3.14" upper="3.14" velocity="100"/>
  </joint>
  <!-- Define prop_forwards_right_link properties -->
  <link name="prop_forwards_right_link">
    <inertial>
      <origin rpy="0 0 0" xyz="1.8738818703401E-06 5.88908199983251E-07 0.00185538704846844"/>
      <mass value="0.00624297252571192"/>
      <inertia ixx="4.64692804665044e-06" ixy="4.07667939979562e-11" ixz="-2.27433285772375e-12" iyy="4.64681400440729e-06" iyz="3.42071727923194e-12" izz="9.10876849788012e-06"/>
    </inertial>
    <visual name="prop_forwards_right_link_visual">
      <origin rpy="0 0 0" xyz="0 0 0"/>
      <geometry>
        <mesh filename="/home/nidhood/Desktop/SWARN_PROJECT/src/drone_model/meshes/visuals/prop_forwards_right_link.dae"/>
      </geometry>
    </visual>
    <collision name="prop_forwards_right_link_collision">
      <origin rpy="0 0 0" xyz="0 0 0"/>
      <geometry>
        <mesh filename="/home/nidhood/Desktop/SWARN_PROJECT/src/drone_model/meshes/collisions/prop_forwards_right_link.stl"/>
      </geometry>
    </collision>
  </link>
  <!-- Define prop_forwards_right_link joint -->
  <joint name="joint_prop_forwards_right_link" type="continuous">
    <origin rpy="0 0 1.0472" xyz="0.099996 0.099994 0.026497"/>
    <parent link="base_link"/>
    <child link="prop_forwards_right_link"/>
    <axis xyz="0 0 1"/>
    <limit effort="100" lower="-3.14" upper="3.14" velocity="100"/>
  </joint>
  <!-- Define prop_backwards_left_link properties -->
  <link name="prop_backwards_left_link">
    <inertial>
      <origin rpy="0 0 0" xyz="2.15410762560708E-08 1.61355459735169E-06 0.00185541109629199"/>
      <mass value="0.00624270876455571"/>
      <inertia ixx="4.64681745240651e-06" ixy="-1.44696572929209e-10" ixz="1.00968266119727e-11" iyy="4.64678537606381e-06" iyz="-8.64251791103487e-12" izz="9.10862981269992e-06"/>
    </inertial>
    <visual name="prop_backwards_left_link_visual">
      <origin rpy="0 0 0" xyz="0 0 0"/>
      <geometry>
        <mesh filename="/home/nidhood/Desktop/SWARN_PROJECT/src/drone_model/meshes/visuals/prop_backwards_left_link.dae"/>
      </geometry>
    </visual>
    <collision name="prop_backwards_left_link_collision">
      <origin rpy="0 0 0" xyz="0 0 0"/>
      <geometry>
        <mesh filename="/home/nidhood/Desktop/SWARN_PROJECT/src/drone_model/meshes/collisions/prop_backwards_left_link.stl"/>
      </geometry>
    </collision>
  </link>
  <!-- Define prop_backwards_left_link joint -->
  <joint name="joint_prop_backwards_left_link" type="continuous">
    <origin rpy="0 0 0.34907" xyz="-0.1 -0.1 0.026497"/>
    <parent link="base_link"/>
    <child link="prop_backwards_left_link"/>
    <axis xyz="0 0 1"/>
    <limit effort="100" lower="-3.14" upper="3.14" velocity="100"/>
  </joint>
  <!-- Define prop_backwards_right_link properties -->
  <link name="prop_backwards_right_link">
    <inertial>
      <origin rpy="0 0 0" xyz="4.12491299339734E-07 -1.6660399568269E-07 0.00185766204825996"/>
      <mass value="0.00622582722578916"/>
      <inertia ixx="4.65687500262372e-06" ixy="1.17883588917842e-10" ixz="-7.89848918095998e-15" iyy="4.6563683794853e-06" iyz="-1.13448664683346e-12" izz="9.12840543730401e-06"/>
    </inertial>
    <visual name="prop_backwards_right_link_visual">
      <origin rpy="0 0 0" xyz="0 0 0"/>
      <geometry>
        <mesh filename="/home/nidhood/Desktop/SWARN_PROJECT/src/drone_model/meshes/visuals/prop_backwards_right_link.dae"/>
      </geometry>
    </visual>
    <collision name="prop_backwards_right_link_collision">
      <origin rpy="0 0 0" xyz="0 0 0"/>
      <geometry>
        <mesh filename="/home/nidhood/Desktop/SWARN_PROJECT/src/drone_model/meshes/collisions/prop_backwards_right_link.stl"/>
      </geometry>
    </collision>
  </link>
  <!-- Define prop_backwards_right_link joint -->
  <joint name="joint_prop_backwards_right_link" type="continuous">
    <origin rpy="0 0 0.7854" xyz="0.099996 -0.1 0.026497"/>
    <parent link="base_link"/>
    <child link="prop_backwards_right_link"/>
    <axis xyz="0 0 1"/>
    <limit effort="100" lower="-3.14" upper="3.14" velocity="100"/>
  </joint>
</robot>
