<?xml version="1.0" encoding="utf-8"?>
<robot xmlns:xacro="http://www.ros.org/wiki/xacro" name="drone_model">

  <!-- Global origin orientation -->
  <xacro:property name="origin_xyz" value="0 0 0" />
  <xacro:property name="origin_rpy" value="0 0 0" />

  <!-- Define global limits -->
  <xacro:property name="lower_limit" value="-3.14" />
  <xacro:property name="upper_limit" value="3.14" />
  <xacro:property name="effort_limit" value="100" />
  <xacro:property name="velocity_limit" value="100" />

  <!-- Define base_link macros properties -->
  <xacro:property name="base_link_xyz" value="-9.1847336179729E-05 0.000415033617555904 -0.000995363919215286" />
  <xacro:property name="base_link_rpy" value="0 0 0" />
  <xacro:property name="base_link_mass" value="0.254307892771006" />
  <xacro:property name="base_link_ixx" value="0.00058785819039432" />
  <xacro:property name="base_link_ixy" value="1.59211619501172E-07" />
  <xacro:property name="base_link_ixz" value="7.61062796150718E-08" />
  <xacro:property name="base_link_iyy" value="0.000540510823170516" />
  <xacro:property name="base_link_iyz" value="-2.06165469438771E-08" />
  <xacro:property name="base_link_izz" value="0.00109842132129949" />

  <!-- Define base_link meshes -->
  <xacro:property name="base_link_visual" value="/home/nidhood/Desktop/SWARN_PROJECT/src/drone_model/meshes/visuals/base_link.dae"/>
  <xacro:property name="base_link_collision" value="/home/nidhood/Desktop/SWARN_PROJECT/src/drone_model/meshes/collisions/base_link.stl"/>                                                    

  <!-- Define base_link properties -->
  <link name="base_link">

    <inertial>
      <origin xyz="${base_link_xyz}" rpy="${base_link_rpy}" />
      <mass value="${base_link_mass}" />
      <inertia ixx="${base_link_ixx}" ixy="${base_link_ixy}" ixz="${base_link_ixz}" iyy="${base_link_iyy}" iyz="${base_link_iyz}" izz="${base_link_izz}" />
    </inertial>

    <visual name="base_link_visual">
      <origin xyz="${origin_xyz}" rpy="${origin_rpy}" />
      <geometry>
        <mesh filename="${base_link_visual}" />
      </geometry>
    </visual>

    <collision name="base_link_collision">
      <origin xyz="${origin_xyz}" rpy="${origin_rpy}" />
      <geometry>
        <mesh filename="${base_link_collision}" />
      </geometry>
    </collision>

  </link>

  <!-- Define prop_forwards_left_link macros properties -->
  <xacro:property name="prop_forwards_left_link_xyz" value="5.71642894409141E-07 -8.54929965155016E-08 0.0018576502110494" />
  <xacro:property name="prop_forwards_left_link_rpy" value="0 0 0" />
  <xacro:property name="prop_forwards_left_link_mass" value="0.00622580390535254" />
  <xacro:property name="prop_forwards_left_link_ixx" value="4.65686406510033E-06" />
  <xacro:property name="prop_forwards_left_link_ixy" value="1.40233492263942E-10" />
  <xacro:property name="prop_forwards_left_link_ixz" value="-2.825811940744E-12" />
  <xacro:property name="prop_forwards_left_link_iyy" value="4.65632288664103E-06" />
  <xacro:property name="prop_forwards_left_link_iyz" value="-2.90803707417964E-12" />
  <xacro:property name="prop_forwards_left_link_izz" value="9.1283491808267E-06" />

  <!-- Define prop_forwards_left_link meshes -->
  <xacro:property name="prop_forwards_left_link_visual" value="/home/nidhood/Desktop/SWARN_PROJECT/src/drone_model/meshes/visuals/prop_forwards_left_link.dae"/>
  <xacro:property name="prop_forwards_left_link_collision" value="/home/nidhood/Desktop/SWARN_PROJECT/src/drone_model/meshes/collisions/prop_forwards_left_link.stl"/>

  <!-- Define prop_forwards_left_link properties -->
  <link name="prop_forwards_left_link">

    <inertial>
      <origin xyz="${prop_forwards_left_link_xyz}" rpy="${prop_forwards_left_link_rpy}" />
      <mass value="${prop_forwards_left_link_mass}" />
      <inertia ixx="${prop_forwards_left_link_ixx}" ixy="${prop_forwards_left_link_ixy}" ixz="${prop_forwards_left_link_ixz}" iyy="${prop_forwards_left_link_iyy}" iyz="${prop_forwards_left_link_iyz}" izz="${prop_forwards_left_link_izz}" />
    </inertial>

    <visual name="prop_forwards_left_link_visual">
      <origin xyz="${origin_xyz}" rpy="${origin_rpy}" />
      <geometry>
        <mesh filename="${prop_forwards_left_link_visual}" />
      </geometry>
    </visual>

    <collision name="prop_forwards_left_link_collision">
      <origin xyz="${origin_xyz}" rpy="${origin_rpy}" />
      <geometry>
        <mesh filename="${prop_forwards_left_link_collision}" />
      </geometry>
    </collision>

  </link>

  <!-- Define prop_forwards_left_link joint configuration -->
  <xacro:property name="prop_forwards_left_link_joint_xyz" value="-0.1 0.099994 0.026497" />
  <xacro:property name="prop_forwards_left_link_joint_rpy" value="0 0 2.3562" />


  <!-- Define prop_forwards_left_link joint -->
  <joint name="joint_prop_forwards_left_link" type="continuous">

    <origin xyz="${prop_forwards_left_link_joint_xyz}" rpy="${prop_forwards_left_link_joint_rpy}" />
    <parent link="base_link" />
    <child link="prop_forwards_left_link" />
    <axis xyz="0 0 1" />
    <limit lower="${lower_limit}" upper="${upper_limit}" effort="${effort_limit}" velocity="${velocity_limit}" />

  </joint>

  <!-- Define prop_forwards_right_link macros properties -->
  <xacro:property name="prop_forwards_right_link_xyz" value="1.8738818703401E-06 5.88908199983251E-07 0.00185538704846844" />
  <xacro:property name="prop_forwards_right_link_rpy" value="0 0 0" />
  <xacro:property name="prop_forwards_right_link_mass" value="0.00624297252571192" />
  <xacro:property name="prop_forwards_right_link_ixx" value="4.64692804665044E-06" />
  <xacro:property name="prop_forwards_right_link_ixy" value="4.07667939979562E-11" />
  <xacro:property name="prop_forwards_right_link_ixz" value="-2.27433285772375E-12" />
  <xacro:property name="prop_forwards_right_link_iyy" value="4.64681400440729E-06" />
  <xacro:property name="prop_forwards_right_link_iyz" value="3.42071727923194E-12" />
  <xacro:property name="prop_forwards_right_link_izz" value="9.10876849788012E-06" />

  <!-- Define prop_forwards_right_link meshes -->
  <xacro:property name="prop_forwards_right_link_visual" value="/home/nidhood/Desktop/SWARN_PROJECT/src/drone_model/meshes/visuals/prop_forwards_right_link.dae"/>
  <xacro:property name="prop_forwards_right_link_collision" value="/home/nidhood/Desktop/SWARN_PROJECT/src/drone_model/meshes/collisions/prop_forwards_right_link.stl"/>

  <!-- Define prop_forwards_right_link properties -->
  <link name="prop_forwards_right_link">

    <inertial>
      <origin xyz="${prop_forwards_right_link_xyz}" rpy="${prop_forwards_right_link_rpy}" />
      <mass value="${prop_forwards_right_link_mass}" />
      <inertia ixx="${prop_forwards_right_link_ixx}" ixy="${prop_forwards_right_link_ixy}" ixz="${prop_forwards_right_link_ixz}" iyy="${prop_forwards_right_link_iyy}" iyz="${prop_forwards_right_link_iyz}" izz="${prop_forwards_right_link_izz}" />
    </inertial>

    <visual name="prop_forwards_right_link_visual">
      <origin xyz="${origin_xyz}" rpy="${origin_rpy}" />
      <geometry>
        <mesh filename="${prop_forwards_right_link_visual}" />
      </geometry>
    </visual>

    <collision name="prop_forwards_right_link_collision">
      <origin xyz="${origin_xyz}" rpy="${origin_rpy}" />
      <geometry>
        <mesh filename="${prop_forwards_right_link_collision}" />
      </geometry>
    </collision>

  </link>

  <!-- Define prop_forwards_right_link joint configuration -->
  <xacro:property name="prop_forwards_right_link_joint_xyz" value="0.099996 0.099994 0.026497" />
  <xacro:property name="prop_forwards_right_link_joint_rpy" value="0 0 1.0472" />

  <!-- Define prop_forwards_right_link joint -->
  <joint name="joint_prop_forwards_right_link" type="continuous">

    <origin xyz="${prop_forwards_right_link_joint_xyz}" rpy="${prop_forwards_right_link_joint_rpy}" />
    <parent link="base_link" />
    <child link="prop_forwards_right_link" />
    <axis xyz="0 0 1" />
    <limit lower="${lower_limit}" upper="${upper_limit}" effort="${effort_limit}" velocity="${velocity_limit}" />

  </joint>

  <!-- Define prop_backwards_left_link macros properties -->
  <xacro:property name="prop_backwards_left_link_xyz" value="2.15410762560708E-08 1.61355459735169E-06 0.00185541109629199" />
  <xacro:property name="prop_backwards_left_link_rpy" value="0 0 0" />
  <xacro:property name="prop_backwards_left_link_mass" value="0.00624270876455571" />
  <xacro:property name="prop_backwards_left_link_ixx" value="4.64681745240651E-06" />
  <xacro:property name="prop_backwards_left_link_ixy" value="-1.44696572929209E-10" />
  <xacro:property name="prop_backwards_left_link_ixz" value="1.00968266119727E-11" />
  <xacro:property name="prop_backwards_left_link_iyy" value="4.64678537606381E-06" />
  <xacro:property name="prop_backwards_left_link_iyz" value="-8.64251791103487E-12" />
  <xacro:property name="prop_backwards_left_link_izz" value="9.10862981269992E-06" />

  <!-- Define prop_backwards_left_link meshes -->
  <xacro:property name="prop_backwards_left_link_visual" value="/home/nidhood/Desktop/SWARN_PROJECT/src/drone_model/meshes/visuals/prop_backwards_left_link.dae"/>
  <xacro:property name="prop_backwards_left_link_collision" value="/home/nidhood/Desktop/SWARN_PROJECT/src/drone_model/meshes/collisions/prop_backwards_left_link.stl"/>

  <!-- Define prop_backwards_left_link properties -->
  <link name="prop_backwards_left_link">

    <inertial>
      <origin xyz="${prop_backwards_left_link_xyz}" rpy="${prop_backwards_left_link_rpy}" />
      <mass value="${prop_backwards_left_link_mass}" />
      <inertia ixx="${prop_backwards_left_link_ixx}" ixy="${prop_backwards_left_link_ixy}" ixz="${prop_backwards_left_link_ixz}" iyy="${prop_backwards_left_link_iyy}" iyz="${prop_backwards_left_link_iyz}" izz="${prop_backwards_left_link_izz}" />
    </inertial>

    <visual name="prop_backwards_left_link_visual">
      <origin xyz="${origin_xyz}" rpy="${origin_rpy}" />
      <geometry>
        <mesh filename="${prop_backwards_left_link_visual}" />
      </geometry>
    </visual>

    <collision name="prop_backwards_left_link_collision">
      <origin xyz="${origin_xyz}" rpy="${origin_rpy}" />
      <geometry>
        <mesh filename="${prop_backwards_left_link_collision}" />
      </geometry>
    </collision>

  </link>

  <!-- Define prop_backwards_left_link joint configuration -->
  <xacro:property name="prop_backwards_left_link_joint_xyz" value="-0.1 -0.1 0.026497" />
  <xacro:property name="prop_backwards_left_link_joint_rpy" value="0 0 0.34907" />

  <!-- Define prop_backwards_left_link joint -->
  <joint name="joint_prop_backwards_left_link" type="continuous">
    
    <origin xyz="${prop_backwards_left_link_joint_xyz}" rpy="${prop_backwards_left_link_joint_rpy}" />
    <parent link="base_link" />
    <child  link="prop_backwards_left_link" />
    <axis   xyz="0 0 1" />
    <limit  lower="${lower_limit}" upper="${upper_limit}" effort="${effort_limit}" velocity="${velocity_limit}" />

  </joint>

  <!-- Define prop_backwards_right_link macros properties -->
  <xacro:property name="prop_backwards_right_link_xyz"  value="4.12491299339734E-07 -1.6660399568269E-07 0.00185766204825996" />
  <xacro:property name="prop_backwards_right_link_rpy"  value="0 0 0" />
  <xacro:property name="prop_backwards_right_link_mass" value="0.00622582722578916" />
  <xacro:property name="prop_backwards_right_link_ixx"  value="4.65687500262372E-06" />
  <xacro:property name="prop_backwards_right_link_ixy"  value="1.17883588917842E-10" />
  <xacro:property name="prop_backwards_right_link_ixz"  value="-7.89848918095998E-15" />
  <xacro:property name="prop_backwards_right_link_iyy"  value="4.6563683794853E-06" />
  <xacro:property name="prop_backwards_right_link_iyz"  value="-1.13448664683346E-12" />
  <xacro:property name="prop_backwards_right_link_izz"  value="9.12840543730401E-06" />

  <!-- Define prop_backwards_right_link meshes -->
  <xacro:property name="prop_backwards_right_link_visual"     value="/home/nidhood/Desktop/SWARN_PROJECT/src/drone_model/meshes/visuals/prop_backwards_right_link.dae"/>
  <xacro:property name="prop_backwards_right_link_collision"  value="/home/nidhood/Desktop/SWARN_PROJECT/src/drone_model/meshes/collisions/prop_backwards_right_link.stl"/>

  <!-- Define prop_backwards_right_link properties -->
  <link name="prop_backwards_right_link">
    <inertial>
      <origin xyz="${prop_backwards_right_link_xyz}" rpy="${prop_backwards_right_link_rpy}" />
      <mass value="${prop_backwards_right_link_mass}" />
      <inertia ixx="${prop_backwards_right_link_ixx}" ixy="${prop_backwards_right_link_ixy}" ixz="${prop_backwards_right_link_ixz}" iyy="${prop_backwards_right_link_iyy}" iyz="${prop_backwards_right_link_iyz}" izz="${prop_backwards_right_link_izz}" />
    </inertial>

    <visual name="prop_backwards_right_link_visual">
      <origin xyz="${origin_xyz}" rpy="${origin_rpy}" />
      <geometry>
        <mesh filename="${prop_backwards_right_link_visual}" />
      </geometry>
    </visual>

    <collision name="prop_backwards_right_link_collision">
      <origin xyz="${origin_xyz}" rpy="${origin_rpy}" />
      <geometry>
        <mesh filename="${prop_backwards_right_link_collision}" />
      </geometry>
    </collision>

  </link>

  <!-- Define prop_backwards_right_link joint configuration -->
  <xacro:property name="prop_backwards_right_link_joint_xyz" value="0.099996 -0.1 0.026497" />
  <xacro:property name="prop_backwards_right_link_joint_rpy" value="0 0 0.7854" />

  <!-- Define prop_backwards_right_link joint -->
  <joint name="joint_prop_backwards_right_link" type="continuous">
  
    <origin xyz="${prop_backwards_right_link_joint_xyz}" rpy="${prop_backwards_right_link_joint_rpy}" />
    <parent link="base_link" />
    <child link="prop_backwards_right_link" />
    <axis xyz="0 0 1" />
    <limit lower="${lower_limit}" upper="${upper_limit}" effort="${effort_limit}" velocity="${velocity_limit}" />
    
  </joint>

</robot>